Workbook

Sheet Dashboard
A1: GDPR / Privacy Governance Dashboard – Autoghinzani
A2: Monitoraggio readiness ispettiva: compilare Checklist_GDPR e Azioni. Il dashboard si aggiorna tramite formule.
A4: Controlli totali | C4: OK | E4: KO | G4: Compliance | J4: Stato Checklist | K4: Conteggio
A5: =COUNTA(Checklist_GDPR!$D$7:$D$156) -> 150 | C5: =COUNTIF(Checklist_GDPR!$E$7:$E$156,"OK") -> 13 | E5: =COUNTIF(Checklist_GDPR!$E$7:$E$156,"KO") -> 2 | G5: =IF((C5+E5)=0,0,C5/(C5+E5)) -> 0.86666667 | J5: OK | K5: =COUNTIF(Checklist_GDPR!$E$7:$E$156,"OK") -> 13
A6: Da compilare | C6: Azioni totali | E6: Azioni completate | G6: Azioni scadute | J6: KO | K6: =COUNTIF(Checklist_GDPR!$E$7:$E$156,"KO") -> 2
A7: =A5-C5-E5-COUNTIF(Checklist_GDPR!$E$7:$E$156,"Non applicabile") -> 133 | C7: =COUNTIF(Azioni!$D$5:$D$124,"?*") -> 1 | E7: =COUNTIF(Azioni!$G$5:$G$124,"Completata") -> 0 | G7: =COUNTIF(Azioni!$L$5:$L$124,"Sì") -> 1 | J7: Non applicabile | K7: =COUNTIF(Checklist_GDPR!$E$7:$E$156,"Non applicabile") -> 2
J8: Da compilare | K8: =A5-C5-E5-COUNTIF(Checklist_GDPR!$E$7:$E$156,"Non applicabile") -> 133
A9: Readiness sintetica
A10: Indice readiness | B10: =IF((C5+E5)=0,"Da avviare",IF(G5>=0.9,"Adeguato",IF(G5>=0.7,"Attenzione","Critico"))) -> Attenzione
A11: Priorità intervento | B11: =IF(E5>0,"Aprire remediation per ogni KO","Mantenere evidenze aggiornate") -> Aprire remediation per ogni KO
A12: Azioni svolte | B12: =IF(C7=0,0,E7/C7) -> 0
A13: Sintesi compliance per sezione
A15: 1. GOVERNANCE PRIVACY | B15: =COUNTIF(Checklist_GDPR!$B$7:$B$156,A15) -> 12 | C15: =COUNTIFS(Checklist_GDPR!$B$7:$B$156,A15,Checklist_GDPR!$E$7:$E$156,"OK") -> 3 | D15: =COUNTIFS(Checklist_GDPR!$B$7:$B$156,A15,Checklist_GDPR!$E$7:$E$156,"KO") -> 0 | E15: =COUNTIFS(Checklist_GDPR!$B$7:$B$156,A15,Checklist_GDPR!$E$7:$E$156,"Non applicabile") -> 1 | F15: =B15-C15-D15-E15 -> 8 | G15: =IF((C15+D15)=0,0,C15/(C15+D15)) -> 1 | H15: =IF((C15+D15)=0,"Da valutare",IF(G15>=0.9,"Adeguato",IF(G15>=0.7,"Attenzione","Critico"))) -> Adeguato
A16: 2. REGISTRO DEI TRATTAMENTI | B16: =COUNTIF(Checklist_GDPR!$B$7:$B$156,A16) -> 10 | C16: =COUNTIFS(Checklist_GDPR!$B$7:$B$156,A16,Checklist_GDPR!$E$7:$E$156,"OK") -> 0 | D16: =COUNTIFS(Checklist_GDPR!$B$7:$B$156,A16,Checklist_GDPR!$E$7:$E$156,"KO") -> 0 | E16: =COUNTIFS(Checklist_GDPR!$B$7:$B$156,A16,Checklist_GDPR!$E$7:$E$156,"Non applicabile") -> 0 | F16: =B16-C16-D16-E16 -> 10 | G16: =IF((C16+D16)=0,0,C16/(C16+D16)) -> 0 | H16: =IF((C16+D16)=0,"Da valutare",IF(G16>=0.9,"Adeguato",IF(G16>=0.7,"Attenzione","Critico"))) -> Da valutare
A17: 3. INFORMATIVE PRIVACY | B17: =COUNTIF(Checklist_GDPR!$B$7:$B$156,A17) -> 14 | C17: =COUNTIFS(Checklist_GDPR!$B$7:$B$156,A17,Checklist_GDPR!$E$7:$E$156,"OK") -> 3 | D17: =COUNTIFS(Checklist_GDPR!$B$7:$B$156,A17,Checklist_GDPR!$E$7:$E$156,"KO") -> 2 | E17: =COUNTIFS(Checklist_GDPR!$B$7:$B$156,A17,Checklist_GDPR!$E$7:$E$156,"Non applicabile") -> 1 | F17: =B17-C17-D17-E17 -> 8 | G17: =IF((C17+D17)=0,0,C17/(C17+D17)) -> 0.6 | H17: =IF((C17+D17)=0,"Da valutare",IF(G17>=0.9,"Adeguato",IF(G17>=0.7,"Attenzione","Critico"))) -> Critico
A18: 4. AUTORIZZAZIONI E PERSONALE | B18: =COUNTIF(Checklist_GDPR!$B$7:$B$156,A18) -> 14 | C18: =COUNTIFS(Checklist_GDPR!$B$7:$B$156,A18,Checklist_GDPR!$E$7:$E$156,"OK") -> 0 | D18: =COUNTIFS(Checklist_GDPR!$B$7:$B$156,A18,Checklist_GDPR!$E$7:$E$156,"KO") -> 0 | E18: =COUNTIFS(Checklist_GDPR!$B$7:$B$156,A18,Checklist_GDPR!$E$7:$E$156,"Non applicabile") -> 0 | F18: =B18-C18-D18-E18 -> 14 | G18: =IF((C18+D18)=0,0,C18/(C18+D18)) -> 0 | H18: =IF((C18+D18)=0,"Da valutare",IF(G18>=0.9,"Adeguato",IF(G18>=0.7,"Attenzione","Critico"))) -> Da valutare
A19: 5. RESPONSABILI ESTERNI | B19: =COUNTIF(Checklist_GDPR!$B$7:$B$156,A19) -> 8 | C19: =COUNTIFS(Checklist_GDPR!$B$7:$B$156,A19,Checklist_GDPR!$E$7:$E$156,"OK") -> 0 | D19: =COUNTIFS(Checklist_GDPR!$B$7:$B$156,A19,Checklist_GDPR!$E$7:$E$156,"KO") -> 0 | E19: =COUNTIFS(Checklist_GDPR!$B$7:$B$156,A19,Checklist_GDPR!$E$7:$E$156,"Non applicabile") -> 0 | F19: =B19-C19-D19-E19 -> 8 | G19: =IF((C19+D19)=0,0,C19/(C19+D19)) -> 0 | H19: =IF((C19+D19)=0,"Da valutare",IF(G19>=0.9,"Adeguato",IF(G19>=0.7,"Attenzione","Critico"))) -> Da valutare
A20: 6. SICUREZZA INFORMATICA | B20: =COUNTIF(Checklist_GDPR!$B$7:$B$156,A20) -> 20 | C20: =COUNTIFS(Checklist_GDPR!$B$7:$B$156,A20,Checklist_GDPR!$E$7:$E$156,"OK") -> 0 | D20: =COUNTIFS(Checklist_GDPR!$B$7:$B$156,A20,Checklist_GDPR!$E$7:$E$156,"KO") -> 0 | E20: =COUNTIFS(Checklist_GDPR!$B$7:$B$156,A20,Checklist_GDPR!$E$7:$E$156,"Non applicabile") -> 0 | F20: =B20-C20-D20-E20 -> 20 | G20: =IF((C20+D20)=0,0,C20/(C20+D20)) -> 0 | H20: =IF((C20+D20)=0,"Da valutare",IF(G20>=0.9,"Adeguato",IF(G20>=0.7,"Attenzione","Critico"))) -> Da valutare
A21: 7. ANALISI RISCHI E ACCOUNTABILITY | B21: =COUNTIF(Checklist_GDPR!$B$7:$B$156,A21) -> 10 | C21: =COUNTIFS(Checklist_GDPR!$B$7:$B$156,A21,Checklist_GDPR!$E$7:$E$156,"OK") -> 7 | D21: =COUNTIFS(Checklist_GDPR!$B$7:$B$156,A21,Checklist_GDPR!$E$7:$E$156,"KO") -> 0 | E21: =COUNTIFS(Checklist_GDPR!$B$7:$B$156,A21,Checklist_GDPR!$E$7:$E$156,"Non applicabile") -> 0 | F21: =B21-C21-D21-E21 -> 3 | G21: =IF((C21+D21)=0,0,C21/(C21+D21)) -> 1 | H21: =IF((C21+D21)=0,"Da valutare",IF(G21>=0.9,"Adeguato",IF(G21>=0.7,"Attenzione","Critico"))) -> Adeguato
A22: 8. DIRITTI DEGLI INTERESSATI | B22: =COUNTIF(Checklist_GDPR!$B$7:$B$156,A22) -> 6 | C22: =COUNTIFS(Checklist_GDPR!$B$7:$B$156,A22,Checklist_GDPR!$E$7:$E$156,"OK") -> 0 | D22: =COUNTIFS(Checklist_GDPR!$B$7:$B$156,A22,Checklist_GDPR!$E$7:$E$156,"KO") -> 0 | E22: =COUNTIFS(Checklist_GDPR!$B$7:$B$156,A22,Checklist_GDPR!$E$7:$E$156,"Non applicabile") -> 0 | F22: =B22-C22-D22-E22 -> 6 | G22: =IF((C22+D22)=0,0,C22/(C22+D22)) -> 0 | H22: =IF((C22+D22)=0,"Da valutare",IF(G22>=0.9,"Adeguato",IF(G22>=0.7,"Attenzione","Critico"))) -> Da valutare
A23: 9. CONSENSI E MARKETING | B23: =COUNTIF(Checklist_GDPR!$B$7:$B$156,A23) -> 6 | C23: =COUNTIFS(Checklist_GDPR!$B$7:$B$156,A23,Checklist_GDPR!$E$7:$E$156,"OK") -> 0 | D23: =COUNTIFS(Checklist_GDPR!$B$7:$B$156,A23,Checklist_GDPR!$E$7:$E$156,"KO") -> 0 | E23: =COUNTIFS(Checklist_GDPR!$B$7:$B$156,A23,Checklist_GDPR!$E$7:$E$156,"Non applicabile") -> 0 | F23: =B23-C23-D23-E23 -> 6 | G23: =IF((C23+D23)=0,0,C23/(C23+D23)) -> 0 | H23: =IF((C23+D23)=0,"Da valutare",IF(G23>=0.9,"Adeguato",IF(G23>=0.7,"Attenzione","Critico"))) -> Da valutare
A24: 10. VIDEOSORVEGLIANZA | B24: =COUNTIF(Checklist_GDPR!$B$7:$B$156,A24) -> 10 | C24: =COUNTIFS(Checklist_GDPR!$B$7:$B$156,A24,Checklist_GDPR!$E$7:$E$156,"OK") -> 0 | D24: =COUNTIFS(Checklist_GDPR!$B$7:$B$156,A24,Checklist_GDPR!$E$7:$E$156,"KO") -> 0 | E24: =COUNTIFS(Checklist_GDPR!$B$7:$B$156,A24,Checklist_GDPR!$E$7:$E$156,"Non applicabile") -> 0 | F24: =B24-C24-D24-E24 -> 10 | G24: =IF((C24+D24)=0,0,C24/(C24+D24)) -> 0 | H24: =IF((C24+D24)=0,"Da valutare",IF(G24>=0.9,"Adeguato",IF(G24>=0.7,"Attenzione","Critico"))) -> Da valutare
A25: 11. SITO WEB E COOKIE | B25: =COUNTIF(Checklist_GDPR!$B$7:$B$156,A25) -> 7 | C25: =COUNTIFS(Checklist_GDPR!$B$7:$B$156,A25,Checklist_GDPR!$E$7:$E$156,"OK") -> 0 | D25: =COUNTIFS(Checklist_GDPR!$B$7:$B$156,A25,Checklist_GDPR!$E$7:$E$156,"KO") -> 0 | E25: =COUNTIFS(Checklist_GDPR!$B$7:$B$156,A25,Checklist_GDPR!$E$7:$E$156,"Non applicabile") -> 0 | F25: =B25-C25-D25-E25 -> 7 | G25: =IF((C25+D25)=0,0,C25/(C25+D25)) -> 0 | H25: =IF((C25+D25)=0,"Da valutare",IF(G25>=0.9,"Adeguato",IF(G25>=0.7,"Attenzione","Critico"))) -> Da valutare
A26: 12. DOCUMENTI ISO / CYBERSECURITY | B26: =COUNTIF(Checklist_GDPR!$B$7:$B$156,A26) -> 10 | C26: =COUNTIFS(Checklist_GDPR!$B$7:$B$156,A26,Checklist_GDPR!$E$7:$E$156,"OK") -> 0 | D26: =COUNTIFS(Checklist_GDPR!$B$7:$B$156,A26,Checklist_GDPR!$E$7:$E$156,"KO") -> 0 | E26: =COUNTIFS(Checklist_GDPR!$B$7:$B$156,A26,Checklist_GDPR!$E$7:$E$156,"Non applicabile") -> 0 | F26: =B26-C26-D26-E26 -> 10 | G26: =IF((C26+D26)=0,0,C26/(C26+D26)) -> 0 | H26: =IF((C26+D26)=0,"Da valutare",IF(G26>=0.9,"Adeguato",IF(G26>=0.7,"Attenzione","Critico"))) -> Da valutare
... A28: 14. VERIFICHE PRATICHE DA FARE IN AUDIT | B28: =COUNTIF(Checklist_GDPR!$B$7:$B$156,A28) -> 12 | C28: =COUNTIFS(Checklist_GDPR!$B$7:$B$156,A28,Checklist_GDPR!$E$7:$E$156,"OK") -> 0 | D28: =COUNTIFS(Checklist_GDPR!$B$7:$B$156,A28,Checklist_GDPR!$E$7:$E$156,"KO") -> 0 | E28: =COUNTIFS(Checklist_GDPR!$B$7:$B$156,A28,Checklist_GDPR!$E$7:$E$156,"Non applicabile") -> 0 | F28: =B28-C28-D28-E28 -> 12 | G28: =IF((C28+D28)=0,0,C28/(C28+D28)) -> 0 | H28: =IF((C28+D28)=0,"Da valutare",IF(G28>=0.9,"Adeguato",IF(G28>=0.7,"Attenzione","Critico"))) -> Da valutare
A29: TOTALE | B29: =SUM(B15:B28) -> 150 | C29: =SUM(C15:C28) -> 13 | D29: =SUM(D15:D28) -> 2 | E29: =SUM(E15:E28) -> 2 | F29: =SUM(F15:F28) -> 133 | G29: =IF((C29+D29)=0,0,C29/(C29+D29)) -> 0.86666667 | H29: =IF((C29+D29)=0,"Da valutare",IF(G29>=0.9,"Adeguato",IF(G29>=0.7,"Attenzione","Critico"))) -> Attenzione
A31: Dashboard azioni svolte / remediation
A33: Completata | B33: =COUNTIF(Azioni!$G$5:$G$124,A33) -> 0 | C33: =IF($C$7=0,0,B33/$C$7) -> 0 | D33: Azioni chiuse con evidenza
A34: In corso | B34: =COUNTIF(Azioni!$G$5:$G$124,A34) -> 1 | C34: =IF($C$7=0,0,B34/$C$7) -> 1 | D34: Azioni avviate ma non chiuse
A35: Da avviare | B35: =COUNTIF(Azioni!$G$5:$G$124,A35) -> 0 | C35: =IF($C$7=0,0,B35/$C$7) -> 0 | D35: Azioni non ancora partite
A36: Bloccata | B36: =COUNTIF(Azioni!$G$5:$G$124,A36) -> 0 | C36: =IF($C$7=0,0,B36/$C$7) -> 0 | D36: Azioni da sbloccare
A37: Scadute | B37: =COUNTIF(Azioni!$L$5:$L$124,"Sì") -> 1 | C37: =IF($C$7=0,0,B37/$C$7) -> 1 | D37: Azioni non completate oltre scadenza

Sheet Checklist_GDPR
A1: Checklist Audit GDPR – Documentazione essenziale in caso di ispezione | Società: Autoghinzani
A2: Obiettivo | B2: Verifica completezza documentale e readiness ispettiva GDPR / Garante Privacy / audit cliente / ISO 27001
A3: Regola calcolo | B3: Compliance = OK / (OK + KO). I Non applicabile non incidono sul denominatore.
A4: Data ultimo aggiornamento | B4: =TODAY() -> 46150
A6: ID | B6: Sezione | C6: Ambito | D6: Requisito / Documento / Controllo | E6: Stato | F6: Owner | G6: Priorità | H6: Scadenza | I6: Evidenza presente | J6: Link/Repository evidenza | K6: Note | L6: Punteggio | M6: Esito governance | N6: Azione suggerita
A7: CTR-001 | B7: 1. GOVERNANCE PRIVACY | C7: Documenti societari e ruoli | D7: Organigramma privacy aggiornato | E7: OK | G7: Critica | I7: Sì | L7: =IF(E7="OK",1,IF(E7="KO",0,"")) -> 1 | M7: =IF(E7="OK","Conforme",IF(E7="KO","Non conforme",IF(E7="Non applicabile","N/A","Da compilare"))) -> Conforme | N7: =IF(E7="KO","Aprire azione correttiva in sheet Azioni",IF(E7="OK","Archiviare evidenza",IF(E7="Non applicabile","Motivare N/A nelle note","Selezionare stato"))) -> Archiviare evidenza
A8: CTR-002 | B8: 1. GOVERNANCE PRIVACY | C8: Documenti societari e ruoli | D8: Nomina Titolare del trattamento | E8: OK | G8: Media | L8: =IF(E8="OK",1,IF(E8="KO",0,"")) -> 1 | M8: =IF(E8="OK","Conforme",IF(E8="KO","Non conforme",IF(E8="Non applicabile","N/A","Da compilare"))) -> Conforme | N8: =IF(E8="KO","Aprire azione correttiva in sheet Azioni",IF(E8="OK","Archiviare evidenza",IF(E8="Non applicabile","Motivare N/A nelle note","Selezionare stato"))) -> Archiviare evidenza
A9: CTR-003 | B9: 1. GOVERNANCE PRIVACY | C9: Documenti societari e ruoli | D9: Nomina eventuale Contitolare | E9: Non applicabile | G9: Media | L9: =IF(E9="OK",1,IF(E9="KO",0,"")) | M9: =IF(E9="OK","Conforme",IF(E9="KO","Non conforme",IF(E9="Non applicabile","N/A","Da compilare"))) -> N/A | N9: =IF(E9="KO","Aprire azione correttiva in sheet Azioni",IF(E9="OK","Archiviare evidenza",IF(E9="Non applicabile","Motivare N/A nelle note","Selezionare stato"))) -> Motivare N/A nelle note
A10: CTR-004 | B10: 1. GOVERNANCE PRIVACY | C10: Documenti societari e ruoli | D10: Nomina Amministratori di Sistema (ADS) | G10: Media | L10: =IF(E10="OK",1,IF(E10="KO",0,"")) | M10: =IF(E10="OK","Conforme",IF(E10="KO","Non conforme",IF(E10="Non applicabile","N/A","Da compilare"))) -> Da compilare | N10: =IF(E10="KO","Aprire azione correttiva in sheet Azioni",IF(E10="OK","Archiviare evidenza",IF(E10="Non applicabile","Motivare N/A nelle note","Selezionare stato"))) -> Selezionare stato
A11: CTR-005 | B11: 1. GOVERNANCE PRIVACY | C11: Documenti societari e ruoli | D11: Registro ADS con funzioni attribuite | G11: Media | L11: =IF(E11="OK",1,IF(E11="KO",0,"")) | M11: =IF(E11="OK","Conforme",IF(E11="KO","Non conforme",IF(E11="Non applicabile","N/A","Da compilare"))) -> Da compilare | N11: =IF(E11="KO","Aprire azione correttiva in sheet Azioni",IF(E11="OK","Archiviare evidenza",IF(E11="Non applicabile","Motivare N/A nelle note","Selezionare stato"))) -> Selezionare stato
A12: CTR-006 | B12: 1. GOVERNANCE PRIVACY | C12: Documenti societari e ruoli | D12: Verifiche annuali ADS | G12: Media | L12: =IF(E12="OK",1,IF(E12="KO",0,"")) | M12: =IF(E12="OK","Conforme",IF(E12="KO","Non conforme",IF(E12="Non applicabile","N/A","Da compilare"))) -> Da compilare | N12: =IF(E12="KO","Aprire azione correttiva in sheet Azioni",IF(E12="OK","Archiviare evidenza",IF(E12="Non applicabile","Motivare N/A nelle note","Selezionare stato"))) -> Selezionare stato
A13: CTR-007 | B13: 1. GOVERNANCE PRIVACY | C13: Documenti societari e ruoli | D13: Log ADS e conservazione log | G13: Media | L13: =IF(E13="OK",1,IF(E13="KO",0,"")) | M13: =IF(E13="OK","Conforme",IF(E13="KO","Non conforme",IF(E13="Non applicabile","N/A","Da compilare"))) -> Da compilare | N13: =IF(E13="KO","Aprire azione correttiva in sheet Azioni",IF(E13="OK","Archiviare evidenza",IF(E13="Non applicabile","Motivare N/A nelle note","Selezionare stato"))) -> Selezionare stato
A14: CTR-008 | B14: 1. GOVERNANCE PRIVACY | C14: Documenti societari e ruoli | D14: Nomina DPO (se presente/obbligatorio) | E14: OK | G14: Media | L14: =IF(E14="OK",1,IF(E14="KO",0,"")) -> 1 | M14: =IF(E14="OK","Conforme",IF(E14="KO","Non conforme",IF(E14="Non applicabile","N/A","Da compilare"))) -> Conforme | N14: =IF(E14="KO","Aprire azione correttiva in sheet Azioni",IF(E14="OK","Archiviare evidenza",IF(E14="Non applicabile","Motivare N/A nelle note","Selezionare stato"))) -> Archiviare evidenza
A15: CTR-009 | B15: 1. GOVERNANCE PRIVACY | C15: Documenti societari e ruoli | D15: Lettera incarico DPO | G15: Media | L15: =IF(E15="OK",1,IF(E15="KO",0,"")) | M15: =IF(E15="OK","Conforme",IF(E15="KO","Non conforme",IF(E15="Non applicabile","N/A","Da compilare"))) -> Da compilare | N15: =IF(E15="KO","Aprire azione correttiva in sheet Azioni",IF(E15="OK","Archiviare evidenza",IF(E15="Non applicabile","Motivare N/A nelle note","Selezionare stato"))) -> Selezionare stato
A16: CTR-010 | B16: 1. GOVERNANCE PRIVACY | C16: Documenti societari e ruoli | D16: Pubblicazione contatti DPO | G16: Media | L16: =IF(E16="OK",1,IF(E16="KO",0,"")) | M16: =IF(E16="OK","Conforme",IF(E16="KO","Non conforme",IF(E16="Non applicabile","N/A","Da compilare"))) -> Da compilare | N16: =IF(E16="KO","Aprire azione correttiva in sheet Azioni",IF(E16="OK","Archiviare evidenza",IF(E16="Non applicabile","Motivare N/A nelle note","Selezionare stato"))) -> Selezionare stato
A17: CTR-011 | B17: 1. GOVERNANCE PRIVACY | C17: Documenti societari e ruoli | D17: Contratto/lettera incarico consulente privacy | G17: Media | L17: =IF(E17="OK",1,IF(E17="KO",0,"")) | M17: =IF(E17="OK","Conforme",IF(E17="KO","Non conforme",IF(E17="Non applicabile","N/A","Da compilare"))) -> Da compilare | N17: =IF(E17="KO","Aprire azione correttiva in sheet Azioni",IF(E17="OK","Archiviare evidenza",IF(E17="Non applicabile","Motivare N/A nelle note","Selezionare stato"))) -> Selezionare stato
A18: CTR-012 | B18: 1. GOVERNANCE PRIVACY | C18: Documenti societari e ruoli | D18: Organigramma IT/Sicurezza | G18: Media | L18: =IF(E18="OK",1,IF(E18="KO",0,"")) | M18: =IF(E18="OK","Conforme",IF(E18="KO","Non conforme",IF(E18="Non applicabile","N/A","Da compilare"))) -> Da compilare | N18: =IF(E18="KO","Aprire azione correttiva in sheet Azioni",IF(E18="OK","Archiviare evidenza",IF(E18="Non applicabile","Motivare N/A nelle note","Selezionare stato"))) -> Selezionare stato
A19: CTR-013 | B19: 2. REGISTRO DEI TRATTAMENTI | C19: Registro Art. 30 GDPR | D19: Registro trattamenti Titolare aggiornato | G19: Media | L19: =IF(E19="OK",1,IF(E19="KO",0,"")) | M19: =IF(E19="OK","Conforme",IF(E19="KO","Non conforme",IF(E19="Non applicabile","N/A","Da compilare"))) -> Da compilare | N19: =IF(E19="KO","Aprire azione correttiva in sheet Azioni",IF(E19="OK","Archiviare evidenza",IF(E19="Non applicabile","Motivare N/A nelle note","Selezionare stato"))) -> Selezionare stato
A20: CTR-014 | B20: 2. REGISTRO DEI TRATTAMENTI | C20: Registro Art. 30 GDPR | D20: Registro Responsabile esterno (se applicabile) | G20: Media | L20: =IF(E20="OK",1,IF(E20="KO",0,"")) | M20: =IF(E20="OK","Conforme",IF(E20="KO","Non conforme",IF(E20="Non applicabile","N/A","Da compilare"))) -> Da compilare | N20: =IF(E20="KO","Aprire azione correttiva in sheet Azioni",IF(E20="OK","Archiviare evidenza",IF(E20="Non applicabile","Motivare N/A nelle note","Selezionare stato"))) -> Selezionare stato
A21: CTR-015 | B21: 2. REGISTRO DEI TRATTAMENTI | C21: Registro Art. 30 GDPR | D21: Elenco finalità trattamento | G21: Media | L21: =IF(E21="OK",1,IF(E21="KO",0,"")) | M21: =IF(E21="OK","Conforme",IF(E21="KO","Non conforme",IF(E21="Non applicabile","N/A","Da compilare"))) -> Da compilare | N21: =IF(E21="KO","Aprire azione correttiva in sheet Azioni",IF(E21="OK","Archiviare evidenza",IF(E21="Non applicabile","Motivare N/A nelle note","Selezionare stato"))) -> Selezionare stato
A22: CTR-016 | B22: 2. REGISTRO DEI TRATTAMENTI | C22: Registro Art. 30 GDPR | D22: Base giuridica per ogni trattamento | G22: Media | L22: =IF(E22="OK",1,IF(E22="KO",0,"")) | M22: =IF(E22="OK","Conforme",IF(E22="KO","Non conforme",IF(E22="Non applicabile","N/A","Da compilare"))) -> Da compilare | N22: =IF(E22="KO","Aprire azione correttiva in sheet Azioni",IF(E22="OK","Archiviare evidenza",IF(E22="Non applicabile","Motivare N/A nelle note","Selezionare stato"))) -> Selezionare stato
A23: CTR-017 | B23: 2. REGISTRO DEI TRATTAMENTI | C23: Registro Art. 30 GDPR | D23: Tempi conservazione dati | G23: Media | L23: =IF(E23="OK",1,IF(E23="KO",0,"")) | M23: =IF(E23="OK","Conforme",IF(E23="KO","Non conforme",IF(E23="Non applicabile","N/A","Da compilare"))) -> Da compilare | N23: =IF(E23="KO","Aprire azione correttiva in sheet Azioni",IF(E23="OK","Archiviare evidenza",IF(E23="Non applicabile","Motivare N/A nelle note","Selezionare stato"))) -> Selezionare stato
A24: CTR-018 | B24: 2. REGISTRO DEI TRATTAMENTI | C24: Registro Art. 30 GDPR | D24: Categorie interessati | G24: Media | L24: =IF(E24="OK",1,IF(E24="KO",0,"")) | M24: =IF(E24="OK","Conforme",IF(E24="KO","Non conforme",IF(E24="Non applicabile","N/A","Da compilare"))) -> Da compilare | N24: =IF(E24="KO","Aprire azione correttiva in sheet Azioni",IF(E24="OK","Archiviare evidenza",IF(E24="Non applicabile","Motivare N/A nelle note","Selezionare stato"))) -> Selezionare stato
A25: CTR-019 | B25: 2. REGISTRO DEI TRATTAMENTI | C25: Registro Art. 30 GDPR | D25: Categorie dati trattati | G25: Media | L25: =IF(E25="OK",1,IF(E25="KO",0,"")) | M25: =IF(E25="OK","Conforme",IF(E25="KO","Non conforme",IF(E25="Non applicabile","N/A","Da compilare"))) -> Da compilare | N25: =IF(E25="KO","Aprire azione correttiva in sheet Azioni",IF(E25="OK","Archiviare evidenza",IF(E25="Non applicabile","Motivare N/A nelle note","Selezionare stato"))) -> Selezionare stato
A26: CTR-020 | B26: 2. REGISTRO DEI TRATTAMENTI | C26: Registro Art. 30 GDPR | D26: Destinatari dati | G26: Media | L26: =IF(E26="OK",1,IF(E26="KO",0,"")) | M26: =IF(E26="OK","Conforme",IF(E26="KO","Non conforme",IF(E26="Non applicabile","N/A","Da compilare"))) -> Da compilare | N26: =IF(E26="KO","Aprire azione correttiva in sheet Azioni",IF(E26="OK","Archiviare evidenza",IF(E26="Non applicabile","Motivare N/A nelle note","Selezionare stato"))) -> Selezionare stato
... A36: CTR-030 | B36: 3. INFORMATIVE PRIVACY | C36: Informative obbligatorie | D36: Cookie policy | G36: Media | L36: =IF(E36="OK",1,IF(E36="KO",0,"")) | M36: =IF(E36="OK","Conforme",IF(E36="KO","Non conforme",IF(E36="Non applicabile","N/A","Da compilare"))) -> Da compilare | N36: =IF(E36="KO","Aprire azione correttiva in sheet Azioni",IF(E36="OK","Archiviare evidenza",IF(E36="Non applicabile","Motivare N/A nelle note","Selezionare stato"))) -> Selezionare stato
A37: CTR-031 | B37: 3. INFORMATIVE PRIVACY | C37: Informative obbligatorie | D37: Privacy policy sito | E37: OK | G37: Media | L37: =IF(E37="OK",1,IF(E37="KO",0,"")) -> 1 | M37: =IF(E37="OK","Conforme",IF(E37="KO","Non conforme",IF(E37="Non applicabile","N/A","Da compilare"))) -> Conforme | N37: =IF(E37="KO","Aprire azione correttiva in sheet Azioni",IF(E37="OK","Archiviare evidenza",IF(E37="Non applicabile","Motivare N/A nelle note","Selezionare stato"))) -> Archiviare evidenza
A38: CTR-032 | B38: 3. INFORMATIVE PRIVACY | C38: Informative obbligatorie | D38: Informativa marketing | E38: OK | G38: Media | L38: =IF(E38="OK",1,IF(E38="KO",0,"")) -> 1 | M38: =IF(E38="OK","Conforme",IF(E38="KO","Non conforme",IF(E38="Non applicabile","N/A","Da compilare"))) -> Conforme | N38: =IF(E38="KO","Aprire azione correttiva in sheet Azioni",IF(E38="OK","Archiviare evidenza",IF(E38="Non applicabile","Motivare N/A nelle note","Selezionare stato"))) -> Archiviare evidenza
A39: CTR-033 | B39: 3. INFORMATIVE PRIVACY | C39: Informative obbligatorie | D39: Informativa newsletter | E39: OK | G39: Media | L39: =IF(E39="OK",1,IF(E39="KO",0,"")) -> 1 | M39: =IF(E39="OK","Conforme",IF(E39="KO","Non conforme",IF(E39="Non applicabile","N/A","Da compilare"))) -> Conforme | N39: =IF(E39="KO","Aprire azione correttiva in sheet Azioni",IF(E39="OK","Archiviare evidenza",IF(E39="Non applicabile","Motivare N/A nelle note","Selezionare stato"))) -> Archiviare evidenza
A40: CTR-034 | B40: 3. INFORMATIVE PRIVACY | C40: Informative obbligatorie | D40: Informativa eventi/test drive | E40: KO | G40: Media | L40: =IF(E40="OK",1,IF(E40="KO",0,"")) -> 0 | M40: =IF(E40="OK","Conforme",IF(E40="KO","Non conforme",IF(E40="Non applicabile","N/A","Da compilare"))) -> Non conforme | N40: =IF(E40="KO","Aprire azione correttiva in sheet Azioni",IF(E40="OK","Archiviare evidenza",IF(E40="Non applicabile","Motivare N/A nelle note","Selezionare stato"))) -> Aprire azione correttiva in sheet Azioni
A41: CTR-035 | B41: 3. INFORMATIVE PRIVACY | C41: Informative obbligatorie | D41: Informativa geolocalizzazione (se presente) | E41: Non applicabile | G41: Media | L41: =IF(E41="OK",1,IF(E41="KO",0,"")) | M41: =IF(E41="OK","Conforme",IF(E41="KO","Non conforme",IF(E41="Non applicabile","N/A","Da compilare"))) -> N/A | N41: =IF(E41="KO","Aprire azione correttiva in sheet Azioni",IF(E41="OK","Archiviare evidenza",IF(E41="Non applicabile","Motivare N/A nelle note","Selezionare stato"))) -> Motivare N/A nelle note
A42: CTR-036 | B42: 3. INFORMATIVE PRIVACY | C42: Informative obbligatorie | D42: Informativa telecamere dashcam/ADAS (se applicabile) | E42: KO | G42: Media | L42: =IF(E42="OK",1,IF(E42="KO",0,"")) -> 0 | M42: =IF(E42="OK","Conforme",IF(E42="KO","Non conforme",IF(E42="Non applicabile","N/A","Da compilare"))) -> Non conforme | N42: =IF(E42="KO","Aprire azione correttiva in sheet Azioni",IF(E42="OK","Archiviare evidenza",IF(E42="Non applicabile","Motivare N/A nelle note","Selezionare stato"))) -> Aprire azione correttiva in sheet Azioni
A43: CTR-037 | B43: 4. AUTORIZZAZIONI E PERSONALE | C43: Personale autorizzato | D43: Nomine autorizzati al trattamento | G43: Media | L43: =IF(E43="OK",1,IF(E43="KO",0,"")) | M43: =IF(E43="OK","Conforme",IF(E43="KO","Non conforme",IF(E43="Non applicabile","N/A","Da compilare"))) -> Da compilare | N43: =IF(E43="KO","Aprire azione correttiva in sheet Azioni",IF(E43="OK","Archiviare evidenza",IF(E43="Non applicabile","Motivare N/A nelle note","Selezionare stato"))) -> Selezionare stato
A44: CTR-038 | B44: 4. AUTORIZZAZIONI E PERSONALE | C44: Personale autorizzato | D44: Regolamento interno privacy | G44: Media | L44: =IF(E44="OK",1,IF(E44="KO",0,"")) | M44: =IF(E44="OK","Conforme",IF(E44="KO","Non conforme",IF(E44="Non applicabile","N/A","Da compilare"))) -> Da compilare | N44: =IF(E44="KO","Aprire azione correttiva in sheet Azioni",IF(E44="OK","Archiviare evidenza",IF(E44="Non applicabile","Motivare N/A nelle note","Selezionare stato"))) -> Selezionare stato
A45: CTR-039 | B45: 4. AUTORIZZAZIONI E PERSONALE | C45: Personale autorizzato | D45: Policy utilizzo strumenti IT | G45: Media | L45: =IF(E45="OK",1,IF(E45="KO",0,"")) | M45: =IF(E45="OK","Conforme",IF(E45="KO","Non conforme",IF(E45="Non applicabile","N/A","Da compilare"))) -> Da compilare | N45: =IF(E45="KO","Aprire azione correttiva in sheet Azioni",IF(E45="OK","Archiviare evidenza",IF(E45="Non applicabile","Motivare N/A nelle note","Selezionare stato"))) -> Selezionare stato
A46: CTR-040 | B46: 4. AUTORIZZAZIONI E PERSONALE | C46: Personale autorizzato | D46: Policy posta elettronica | G46: Media | L46: =IF(E46="OK",1,IF(E46="KO",0,"")) | M46: =IF(E46="OK","Conforme",IF(E46="KO","Non conforme",IF(E46="Non applicabile","N/A","Da compilare"))) -> Da compilare | N46: =IF(E46="KO","Aprire azione correttiva in sheet Azioni",IF(E46="OK","Archiviare evidenza",IF(E46="Non applicabile","Motivare N/A nelle note","Selezionare stato"))) -> Selezionare stato
A47: CTR-041 | B47: 4. AUTORIZZAZIONI E PERSONALE | C47: Personale autorizzato | D47: Policy password | G47: Media | L47: =IF(E47="OK",1,IF(E47="KO",0,"")) | M47: =IF(E47="OK","Conforme",IF(E47="KO","Non conforme",IF(E47="Non applicabile","N/A","Da compilare"))) -> Da compilare | N47: =IF(E47="KO","Aprire azione correttiva in sheet Azioni",IF(E47="OK","Archiviare evidenza",IF(E47="Non applicabile","Motivare N/A nelle note","Selezionare stato"))) -> Selezionare stato
A48: CTR-042 | B48: 4. AUTORIZZAZIONI E PERSONALE | C48: Personale autorizzato | D48: Policy smart working | G48: Media | L48: =IF(E48="OK",1,IF(E48="KO",0,"")) | M48: =IF(E48="OK","Conforme",IF(E48="KO","Non conforme",IF(E48="Non applicabile","N/A","Da compilare"))) -> Da compilare | N48: =IF(E48="KO","Aprire azione correttiva in sheet Azioni",IF(E48="OK","Archiviare evidenza",IF(E48="Non applicabile","Motivare N/A nelle note","Selezionare stato"))) -> Selezionare stato
A49: CTR-043 | B49: 4. AUTORIZZAZIONI E PERSONALE | C49: Personale autorizzato | D49: Policy BYOD | G49: Media | L49: =IF(E49="OK",1,IF(E49="KO",0,"")) | M49: =IF(E49="OK","Conforme",IF(E49="KO","Non conforme",IF(E49="Non applicabile","N/A","Da compilare"))) -> Da compilare | N49: =IF(E49="KO","Aprire azione correttiva in sheet Azioni",IF(E49="OK","Archiviare evidenza",IF(E49="Non applicabile","Motivare N/A nelle note","Selezionare stato"))) -> Selezionare stato
A50: CTR-044 | B50: 4. AUTORIZZAZIONI E PERSONALE | C50: Personale autorizzato | D50: Policy utilizzo internet | G50: Media | L50: =IF(E50="OK",1,IF(E50="KO",0,"")) | M50: =IF(E50="OK","Conforme",IF(E50="KO","Non conforme",IF(E50="Non applicabile","N/A","Da compilare"))) -> Da compilare | N50: =IF(E50="KO","Aprire azione correttiva in sheet Azioni",IF(E50="OK","Archiviare evidenza",IF(E50="Non applicabile","Motivare N/A nelle note","Selezionare stato"))) -> Selezionare stato
...

Sheet Azioni
A1: Registro Azioni / Remediation – Tracking azioni svolte e aperte
A2: Usare questo foglio per ogni KO o gap rilevato. Compilare Azione correttiva, Owner, Stato e Scadenza. Il Dashboard calcola avanzamento, scaduti e azioni completate.
A4: ID Azione | B4: ID Checklist | C4: Sezione | D4: Azione correttiva | E4: Owner | F4: Priorità | G4: Stato Azione | H4: Data apertura | I4: Scadenza | J4: Data chiusura | K4: % Avanzamento | L4: Scaduta? | M4: Note
A5: =IF(D5<>"","ACT-"&TEXT(ROW()-4,"000"),"") -> ACT-001 | C5: 3. INFORMATIVE PRIVACY | D5: AGGIORNAREINFORMATIVE | F5: Critica | G5: In corso | K5: =IF(G5="Completata",1,IF(G5="In corso",0.5,IF(G5="Bloccata",0.25,IF(G5="Da avviare",0,"")))) -> 0.5 | L5: =IF(D5="","",IF(AND(G5<>"Completata",I5<TODAY()),"Sì","No")) -> Sì
A6: =IF(D6<>"","ACT-"&TEXT(ROW()-4,"000"),"") | K6: =IF(G6="Completata",1,IF(G6="In corso",0.5,IF(G6="Bloccata",0.25,IF(G6="Da avviare",0,"")))) | L6: =IF(D6="","",IF(AND(G6<>"Completata",I6<TODAY()),"Sì","No"))
A7: =IF(D7<>"","ACT-"&TEXT(ROW()-4,"000"),"") | K7: =IF(G7="Completata",1,IF(G7="In corso",0.5,IF(G7="Bloccata",0.25,IF(G7="Da avviare",0,"")))) | L7: =IF(D7="","",IF(AND(G7<>"Completata",I7<TODAY()),"Sì","No"))
A8: =IF(D8<>"","ACT-"&TEXT(ROW()-4,"000"),"") | K8: =IF(G8="Completata",1,IF(G8="In corso",0.5,IF(G8="Bloccata",0.25,IF(G8="Da avviare",0,"")))) | L8: =IF(D8="","",IF(AND(G8<>"Completata",I8<TODAY()),"Sì","No"))
A9: =IF(D9<>"","ACT-"&TEXT(ROW()-4,"000"),"") | K9: =IF(G9="Completata",1,IF(G9="In corso",0.5,IF(G9="Bloccata",0.25,IF(G9="Da avviare",0,"")))) | L9: =IF(D9="","",IF(AND(G9<>"Completata",I9<TODAY()),"Sì","No"))
A10: =IF(D10<>"","ACT-"&TEXT(ROW()-4,"000"),"") | K10: =IF(G10="Completata",1,IF(G10="In corso",0.5,IF(G10="Bloccata",0.25,IF(G10="Da avviare",0,"")))) | L10: =IF(D10="","",IF(AND(G10<>"Completata",I10<TODAY()),"Sì","No"))
A11: =IF(D11<>"","ACT-"&TEXT(ROW()-4,"000"),"") | K11: =IF(G11="Completata",1,IF(G11="In corso",0.5,IF(G11="Bloccata",0.25,IF(G11="Da avviare",0,"")))) | L11: =IF(D11="","",IF(AND(G11<>"Completata",I11<TODAY()),"Sì","No"))
A12: =IF(D12<>"","ACT-"&TEXT(ROW()-4,"000"),"") | K12: =IF(G12="Completata",1,IF(G12="In corso",0.5,IF(G12="Bloccata",0.25,IF(G12="Da avviare",0,"")))) | L12: =IF(D12="","",IF(AND(G12<>"Completata",I12<TODAY()),"Sì","No"))
A13: =IF(D13<>"","ACT-"&TEXT(ROW()-4,"000"),"") | K13: =IF(G13="Completata",1,IF(G13="In corso",0.5,IF(G13="Bloccata",0.25,IF(G13="Da avviare",0,"")))) | L13: =IF(D13="","",IF(AND(G13<>"Completata",I13<TODAY()),"Sì","No"))
A14: =IF(D14<>"","ACT-"&TEXT(ROW()-4,"000"),"") | K14: =IF(G14="Completata",1,IF(G14="In corso",0.5,IF(G14="Bloccata",0.25,IF(G14="Da avviare",0,"")))) | L14: =IF(D14="","",IF(AND(G14<>"Completata",I14<TODAY()),"Sì","No"))
A15: =IF(D15<>"","ACT-"&TEXT(ROW()-4,"000"),"") | K15: =IF(G15="Completata",1,IF(G15="In corso",0.5,IF(G15="Bloccata",0.25,IF(G15="Da avviare",0,"")))) | L15: =IF(D15="","",IF(AND(G15<>"Completata",I15<TODAY()),"Sì","No"))
A16: =IF(D16<>"","ACT-"&TEXT(ROW()-4,"000"),"") | K16: =IF(G16="Completata",1,IF(G16="In corso",0.5,IF(G16="Bloccata",0.25,IF(G16="Da avviare",0,"")))) | L16: =IF(D16="","",IF(AND(G16<>"Completata",I16<TODAY()),"Sì","No"))
A17: =IF(D17<>"","ACT-"&TEXT(ROW()-4,"000"),"") | K17: =IF(G17="Completata",1,IF(G17="In corso",0.5,IF(G17="Bloccata",0.25,IF(G17="Da avviare",0,"")))) | L17: =IF(D17="","",IF(AND(G17<>"Completata",I17<TODAY()),"Sì","No"))
... A124: =IF(D124<>"","ACT-"&TEXT(ROW()-4,"000"),"") | K124: =IF(G124="Completata",1,IF(G124="In corso",0.5,IF(G124="Bloccata",0.25,IF(G124="Da avviare",0,"")))) | L124: =IF(D124="","",IF(AND(G124<>"Completata",I124<TODAY()),"Sì","No"))

Sheet Registro_Evidenze
A1: Registro Evidenze Documentali – Audit GDPR / Ispezione
A4: ID Checklist | B4: Sezione | C4: Documento/Evidenza | D4: Repository / Link / Posizione | E4: Owner | F4: Stato Evidenza | G4: Data verifica | H4: Validità fino a | I4: Note
A5: CTR-001 | B5: 1. GOVERNANCE PRIVACY | C5: Organigramma privacy aggiornato | F5: Presente
A6: CTR-002 | B6: 1. GOVERNANCE PRIVACY | C6: Nomina Titolare del trattamento | F6: Presente
A7: CTR-003 | B7: 1. GOVERNANCE PRIVACY | C7: Nomina eventuale Contitolare
A8: CTR-004 | B8: 1. GOVERNANCE PRIVACY | C8: Nomina Amministratori di Sistema (ADS)
A9: CTR-005 | B9: 1. GOVERNANCE PRIVACY | C9: Registro ADS con funzioni attribuite
A10: CTR-006 | B10: 1. GOVERNANCE PRIVACY | C10: Verifiche annuali ADS
A11: CTR-007 | B11: 1. GOVERNANCE PRIVACY | C11: Log ADS e conservazione log
A12: CTR-008 | B12: 1. GOVERNANCE PRIVACY | C12: Nomina DPO (se presente/obbligatorio)
A13: CTR-009 | B13: 1. GOVERNANCE PRIVACY | C13: Lettera incarico DPO
A14: CTR-010 | B14: 1. GOVERNANCE PRIVACY | C14: Pubblicazione contatti DPO
A15: CTR-011 | B15: 1. GOVERNANCE PRIVACY | C15: Contratto/lettera incarico consulente privacy
A16: CTR-012 | B16: 1. GOVERNANCE PRIVACY | C16: Organigramma IT/Sicurezza
A17: CTR-013 | B17: 2. REGISTRO DEI TRATTAMENTI | C17: Registro trattamenti Titolare aggiornato
A18: CTR-014 | B18: 2. REGISTRO DEI TRATTAMENTI | C18: Registro Responsabile esterno (se applicabile)
... A154: CTR-150 | B154: 14. VERIFICHE PRATICHE DA FARE IN AUDIT | C154: Telecamere non invasive

Sheet Governance_RACI
A1: Matrice Governance / RACI – Privacy, Security, ISO 27001
A4: Area / Processo | B4: Accountable | C4: Responsible | D4: Consulted | E4: Informed | F4: Frequenza controllo | G4: KPI / Evidenza | H4: Risk Rating | I4: Note
A5: 1. GOVERNANCE PRIVACY | F5: Annuale | G5: % compliance sezione / evidenze aggiornate | H5: Medio | I5: Documenti societari e ruoli
A6: 2. REGISTRO DEI TRATTAMENTI | F6: Annuale | G6: % compliance sezione / evidenze aggiornate | H6: Medio | I6: Registro Art. 30 GDPR
A7: 3. INFORMATIVE PRIVACY | F7: Annuale | G7: % compliance sezione / evidenze aggiornate | H7: Medio | I7: Informative obbligatorie
A8: 4. AUTORIZZAZIONI E PERSONALE | F8: Annuale | G8: % compliance sezione / evidenze aggiornate | H8: Medio | I8: Personale autorizzato
A9: 5. RESPONSABILI ESTERNI | F9: Annuale | G9: % compliance sezione / evidenze aggiornate | H9: Medio | I9: Contratti art. 28 GDPR
A10: 6. SICUREZZA INFORMATICA | F10: Trimestrale | G10: % compliance sezione / evidenze aggiornate | H10: Alto | I10: Misure tecniche e organizzative
A11: 7. ANALISI RISCHI E ACCOUNTABILITY | F11: Annuale | G11: % compliance sezione / evidenze aggiornate | H11: Alto | I11: Compliance e risk management
A12: 8. DIRITTI DEGLI INTERESSATI | F12: Semestrale | G12: % compliance sezione / evidenze aggiornate | H12: Medio | I12: Gestione richieste
A13: 9. CONSENSI E MARKETING | F13: Semestrale | G13: % compliance sezione / evidenze aggiornate | H13: Medio | I13: Marketing e profilazione
A14: 10. VIDEOSORVEGLIANZA | F14: Annuale | G14: % compliance sezione / evidenze aggiornate | H14: Alto | I14: Compliance telecamere
A15: 11. SITO WEB E COOKIE | F15: Semestrale | G15: % compliance sezione / evidenze aggiornate | H15: Alto | I15: Compliance digitale
A16: 12. DOCUMENTI ISO / CYBERSECURITY | F16: Annuale | G16: % compliance sezione / evidenze aggiornate | H16: Medio | I16: Governance sicurezza
... A18: 14. VERIFICHE PRATICHE DA FARE IN AUDIT | F18: Trimestrale | G18: % compliance sezione / evidenze aggiornate | H18: Alto | I18: Controlli operativi

Sheet Parametri
A1: Stati Checklist | B1: Stati Azione | C1: Priorità | D1: Sezioni | E1: Stati Evidenza | F1: Risk Rating
A2: OK | B2: Da avviare | C2: Critica | D2: 1. GOVERNANCE PRIVACY | E2: Presente | F2: Basso
A3: KO | B3: In corso | C3: Alta | D3: 2. REGISTRO DEI TRATTAMENTI | E3: Mancante | F3: Medio
A4: Non applicabile | B4: Completata | C4: Media | D4: 3. INFORMATIVE PRIVACY | E4: Parziale | F4: Alto
B5: Bloccata | C5: Bassa | D5: 4. AUTORIZZAZIONI E PERSONALE | E5: Non applicabile | F5: Critico
D6: 5. RESPONSABILI ESTERNI
D7: 6. SICUREZZA INFORMATICA
D8: 7. ANALISI RISCHI E ACCOUNTABILITY
D9: 8. DIRITTI DEGLI INTERESSATI
D10: 9. CONSENSI E MARKETING
D11: 10. VIDEOSORVEGLIANZA
D12: 11. SITO WEB E COOKIE
D13: 12. DOCUMENTI ISO / CYBERSECURITY
D14: 13. EVIDENZE OPERATIVE IMPORTANTI IN CASO DI ISPEZIONE
D15: 14. VERIFICHE PRATICHE DA FARE IN AUDIT

Sheet Istruzioni
A1: Workbook Governance GDPR / Audit Readiness – Autoghinzani
A3: Sezione | B3: Come usarla
A4: Dashboard | B4: Vista executive con compliance complessiva, stato documentazione, distribuzione OK/KO/Non applicabile e avanzamento azioni.
A5: Checklist_GDPR | B5: Compilare la colonna Stato con il menu a tendina: OK, KO o Non applicabile. La % compliance esclude i Non applicabile dal denominatore.
A6: Azioni | B6: Inserire una remediation per ogni KO: owner, priorità, stato, scadenza e note. Il dashboard calcola azioni completate, aperte e scadute.
A7: Registro_Evidenze | B7: Mappare link, repository o posizione delle evidenze documentali da mostrare in caso di ispezione o audit cliente.
A8: Governance_RACI | B8: Assegnare owner e responsabilità per area: Accountable, Responsible, Consulted, Informed, frequenza e KPI.
A9: Parametri | B9: Contiene le liste utilizzate dai menu a tendina. Modificare qui le voci se necessario.
A10: Regola compliance | B10: Compliance = OK / (OK + KO). I Non applicabile sono esclusi dal calcolo; i blank restano da compilare.
